Workbook

Sheet Sheet1
A1: Abuse Data Text | B1: Detection | C1: Toxic | D1: Threat | E1: Obscene | F1: Insult | G1: Racism
A2: এই গুলার জায়গামতো চুঁচড়া লাগিয়ে দেয়া দরকার! যত্তসব ভন্ড!" | B2: 1 | C2: 1 | D2: 0 | E2: 0 | F2: 1 | G2: 0
A3: এই মাদ্রাসার হোগুরকে ডিলডো মেরে শাস্তি দেয়া হোক। | B3: 1 | C3: 1 | D3: 0 | E3: 0 | F3: 1 | G3: 0
A4: নাস্তিকতা মানে ই মানুষিক রোগী । | B4: 1 | C4: 1 | D4: 0 | E4: 0 | F4: 0 | G4: 1
A5: এই বানর !!আপনি কোন জংগল থেকে উদিত হইলেন ? | B5: 1 | C5: 1 | D5: 0 | E5: 0 | F5: 1 | G5: 0
A6: হাহা ভাইকি গাঞ্জা একটু বেশি খাইছেন | B6: 1 | C6: 1 | D6: 0 | E6: 0 | F6: 1 | G6: 0
A7: বলদ মুমিন | B7: 1 | C7: 1 | D7: 0 | E7: 0 | F7: 0 | G7: 1
A8: নিজেরে কি ভাবিস মাদারচোদ? | B8: 1 | C8: 1 | D8: 0 | E8: 1 | F8: 1 | G8: 0
A9: ফালাইয়া দিব মাদারচোদ | B9: 1 | C9: 1 | D9: 1 | E9: 1 | F9: 0 | G9: 0
A10: ঐ লোকটা একটা বোকাচোদা | B10: 1 | C10: 1 | D10: 0 | E10: 0 | F10: 1 | G10: 0
A11: ধর্মান্ধদের জ্ঞান থাকে শিশ্নের আগায়। | B11: 1 | C11: 1 | D11: 0 | E11: 1 | F11: 0 | G11: 0
A12: এরাই পরে সেক্স কন্ট্রোল করতে না পেরে ছাগল লাগাই | B12: 1 | C12: 1 | D12: 0 | E12: 1 | F12: 1 | G12: 0
A13: তোর বৌ আমাকে দিয়ে গোদের জালা মিটাবে | B13: 1 | C13: 1 | D13: 0 | E13: 1 | F13: 0 | G13: 0
... A239: চোর খুনি তোরা, তোদের মত জারোজ এমপি বাংলাদেশের কলঙ্ক | B239: 1 | C239: 1 | D239: 0 | E239: 0 | F239: 0 | G239: 0
A240: 1 | B240: 1 | C240: 1 | D240: 0 | E240: 0 | F240: 0 | G240: 0
A241: অসাধারন পিক বাইঞ্চোদ যেমন বাপ তেমন ছেলে কুলাঙ্গার ডিটেক্টট | B241: 1 | C241: 1 | D241: 0 | E241: 0 | F241: 0 | G241: 0
A242: হাঊয়ার নাতি, তোর হোগা দিয়া ভিজা পাঊরুটি আর ফুলকপি ঢুকামু। আমার ঘরের আলমারি ঢুকামু। জনি | B242: 1 | C242: 1 | D242: 1 | E242: 0 | F242: 0 | G242: 0
A243: কোন নিশিদ্ধ পল্লীতে জন্ম তোর? নাকি কোনো এক রাতের কনডম এক্সিডেন্ট এর ফল তুই? আসলে | B243: 1 | C243: 1 | D243: 0 | E243: 1 | F243: 1 | G243: 0
A244: আরিফ তোর বিচি কেটে ভাগা দিয়ে বিক্রি করে যে টাকা হবে সে টাকা দিয়ে তোর | B244: 1 | C244: 1 | D244: 0 | E244: 1 | F244: 1 | G244: 0
A245: আরিপ্পা কয় কেজি গঞ্জিকা সেবন করসোস?? তোর চোখ এমন ক্যা??? | B245: 1 | C245: 1 | D245: 0 | E245: 1 | F245: 1 | G245: 0
A246: আমি সিউর তুই তোর মার পুটকি দিয়া বাইর হইছস... | B246: 1 | C246: 1 | D246: 0 | E246: 1 | F246: 1 | G246: 0
A247: মেয়েটা আসলেই একটা মাতারী, লেসবু পার্টনার বাছাই করবি ভালো কথা কিন্তু আগে খেয়াল করবি না | B247: 1 | C247: 1 | D247: 0 | E247: 1 | F247: 1 | G247: 0
A248: বাই দ্যা ওয়ে,আরিপ্পা তোর ভাগ্য ভালো আইফেল টাওয়ার টা অনেক দূরে হয়ে গেছে, কাছে ভিত্রে | B248: 1 | C248: 1 | D248: 0 | E248: 1 | F248: 1 | G248: 0
A249: তোর পুটকি দিয়া ভরতো | B249: 1 | C249: 1 | D249: 0 | E249: 1 | F249: 1 | G249: 0
A250: ডাইরেক্ট তাবিজ্জার ভিত্রে ভইরা রাখবো বাইঞ্চুদ | B250: 1 | C250: 1 | D250: 0 | E250: 1 | F250: 1 | G250: 0
A251: আরিপ্পা ফ্রিল্যান্সিং কি তুই বুঝস, তর মত আরিপ্পা যদি ফ্রিল্যান্সিং এর কাজ জানতি তুই | B251: 1 | C251: 1 | D251: 0 | E251: 1 | F251: 1 | G251: 0
A252: হুগা মাইরা কি টাকা ইনকাম করতি | B252: 1 | C252: 1 | D252: 0 | E252: 1 | F252: 1 | G252: 0
... A2628: খাঙ্কি | B2628: 1 | C2628: 1 | D2628: 0 | E2628: 1 | F2628: 1 | G2628: 0
B2629: 1 | C2629: 1 | D2629: 0 | E2629: 1 | F2629: 1 | G2629: 0
A2630: চুদানির পো | B2630: 1 | C2630: 1 | D2630: 0 | E2630: 1 | F2630: 1 | G2630: 0
A2631: শালা চুদানিরমাদ মারানির মাদ্মারানি | B2631: 1 | C2631: 1 | D2631: 0 | E2631: 1 | F2631: 1 | G2631: 0
A2632: তর ভায়েরে চুদানির পো | B2632: 1 | C2632: 1 | D2632: 0 | E2632: 1 | F2632: 1 | G2632: 0
A2633: বান্দির বাচ্চা | B2633: 1 | C2633: 1 | D2633: 0 | E2633: 1 | F2633: 1 | G2633: 0
A2634: ,ভুদামারানি | B2634: 1 | C2634: 1 | D2634: 0 | E2634: 1 | F2634: 1 | G2634: 0
A2635: ধনের পো | B2635: 1 | C2635: 1 | D2635: 0 | E2635: 1 | F2635: 1 | G2635: 0
A2636: মারানিরপোলা | B2636: 1 | C2636: 1 | D2636: 0 | E2636: 1 | F2636: 1 | G2636: 0
A2637: হাওয়া চুদা | B2637: 1 | C2637: 1 | D2637: 0 | E2637: 1 | F2637: 1 | G2637: 0
A2638: লেলি কুত্তা | B2638: 1 | C2638: 1 | D2638: 0 | E2638: 0 | F2638: 1 | G2638: 0
A2639: শালা চুদানিরমাদ মারানির মাদ্মারানি | B2639: 1 | C2639: 1 | D2639: 0 | E2639: 1 | F2639: 1 | G2639: 0
A2640: পুকচুদানি | B2640: 1 | C2640: 1 | D2640: 0 | E2640: 1 | F2640: 1 | G2640: 0
...

Sheet Sheet2
B4: Aspects | C4: Yes | D4: No
B5: Detection | C5: =COUNTIF(Sheet1!B:B,1) -> 4514 | D5: =COUNTIF(Sheet1!B:B,0) -> 5955 | E5: =SUM(C5:D5) -> 10469
B6: Toxic | C6: =COUNTIF(Sheet1!C:C,1) -> 4215 | D6: =COUNTIF(Sheet1!C:C,0) -> 6254
B7: Threat | C7: =COUNTIF(Sheet1!D:D,1) -> 703 | D7: =COUNTIF(Sheet1!D:D,0) -> 9766
B8: Obscene | C8: =COUNTIF(Sheet1!E:E,1) -> 3338 | D8: =COUNTIF(Sheet1!E:E,0) -> 7131
B9: Insult | C9: =COUNTIF(Sheet1!F:F,1) -> 3924 | D9: =COUNTIF(Sheet1!F:F,0) -> 6545
B10: Racism | C10: =COUNTIF(Sheet1!G:G,1) -> 184 | D10: =COUNTIF(Sheet1!G:G,0) -> 10285
